2025-05-25 00:23:18 INFO: Checking for updates to resources.json in case models have been updated.  Note: this behavior can be turned off with download_method=None or download_method=DownloadMethod.REUSE_RESOURCES
Traceback (most recent call last):
  File "/work/tc067/tc067/s2678328/myvenv/lib/python3.10/site-packages/urllib3/connection.py", line 203, in _new_conn
    sock = connection.create_connection(
  File "/work/tc067/tc067/s2678328/myvenv/lib/python3.10/site-packages/urllib3/util/connection.py", line 85, in create_connection
    raise err
  File "/work/tc067/tc067/s2678328/myvenv/lib/python3.10/site-packages/urllib3/util/connection.py", line 73, in create_connection
    sock.connect(sa)
OSError: [Errno 101] Network is unreachable

The above exception was the direct cause of the following exception:

Traceback (most recent call last):
  File "/work/tc067/tc067/s2678328/myvenv/lib/python3.10/site-packages/urllib3/connectionpool.py", line 790, in urlopen
    response = self._make_request(
  File "/work/tc067/tc067/s2678328/myvenv/lib/python3.10/site-packages/urllib3/connectionpool.py", line 491, in _make_request
    raise new_e
  File "/work/tc067/tc067/s2678328/myvenv/lib/python3.10/site-packages/urllib3/connectionpool.py", line 467, in _make_request
    self._validate_conn(conn)
  File "/work/tc067/tc067/s2678328/myvenv/lib/python3.10/site-packages/urllib3/connectionpool.py", line 1096, in _validate_conn
    conn.connect()
  File "/work/tc067/tc067/s2678328/myvenv/lib/python3.10/site-packages/urllib3/connection.py", line 611, in connect
    self.sock = sock = self._new_conn()
  File "/work/tc067/tc067/s2678328/myvenv/lib/python3.10/site-packages/urllib3/connection.py", line 218, in _new_conn
    raise NewConnectionError(
urllib3.exceptions.NewConnectionError: <urllib3.connection.HTTPSConnection object at 0x14e9f7222080>: Failed to establish a new connection: [Errno 101] Network is unreachable

The above exception was the direct cause of the following exception:

Traceback (most recent call last):
  File "/work/y07/shared/cirrus-software/miniconda3/22.11.1-1-py310-gpu/lib/python3.10/site-packages/requests/adapters.py", line 486, in send
    resp = conn.urlopen(
  File "/work/tc067/tc067/s2678328/myvenv/lib/python3.10/site-packages/urllib3/connectionpool.py", line 844, in urlopen
    retries = retries.increment(
  File "/work/tc067/tc067/s2678328/myvenv/lib/python3.10/site-packages/urllib3/util/retry.py", line 515, in increment
    raise MaxRetryError(_pool, url, reason) from reason  # type: ignore[arg-type]
urllib3.exceptions.MaxRetryError: HTTPSConnectionPool(host='raw.githubusercontent.com', port=443): Max retries exceeded with url: /stanfordnlp/stanza-resources/main/resources_1.6.0.json (Caused by NewConnectionError('<urllib3.connection.HTTPSConnection object at 0x14e9f7222080>: Failed to establish a new connection: [Errno 101] Network is unreachable'))

During handling of the above exception, another exception occurred:

Traceback (most recent call last):
  File "/mnt/lustre/e1000/home/tc067/tc067/s2678328/mission-impossible/data/tag_rus.py", line 47, in <module>
    nlp1 = stanza.Pipeline(
  File "/work/tc067/tc067/s2678328/myvenv/lib/python3.10/site-packages/stanza/pipeline/core.py", line 212, in __init__
    download_resources_json(self.dir,
  File "/work/tc067/tc067/s2678328/myvenv/lib/python3.10/site-packages/stanza/resources/common.py", line 444, in download_resources_json
    request_file(
  File "/work/tc067/tc067/s2678328/myvenv/lib/python3.10/site-packages/stanza/resources/common.py", line 152, in request_file
    download_file(url, temppath, proxies, raise_for_status)
  File "/work/tc067/tc067/s2678328/myvenv/lib/python3.10/site-packages/stanza/resources/common.py", line 114, in download_file
    r = requests.get(url, stream=True, proxies=proxies)
  File "/work/y07/shared/cirrus-software/miniconda3/22.11.1-1-py310-gpu/lib/python3.10/site-packages/requests/api.py", line 73, in get
    return request("get", url, params=params, **kwargs)
  File "/work/y07/shared/cirrus-software/miniconda3/22.11.1-1-py310-gpu/lib/python3.10/site-packages/requests/api.py", line 59, in request
    return session.request(method=method, url=url, **kwargs)
  File "/work/y07/shared/cirrus-software/miniconda3/22.11.1-1-py310-gpu/lib/python3.10/site-packages/requests/sessions.py", line 589, in request
    resp = self.send(prep, **send_kwargs)
  File "/work/y07/shared/cirrus-software/miniconda3/22.11.1-1-py310-gpu/lib/python3.10/site-packages/requests/sessions.py", line 703, in send
    r = adapter.send(request, **kwargs)
  File "/work/y07/shared/cirrus-software/miniconda3/22.11.1-1-py310-gpu/lib/python3.10/site-packages/requests/adapters.py", line 519, in send
    raise ConnectionError(e, request=request)
requests.exceptions.ConnectionError: HTTPSConnectionPool(host='raw.githubusercontent.com', port=443): Max retries exceeded with url: /stanfordnlp/stanza-resources/main/resources_1.6.0.json (Caused by NewConnectionError('<urllib3.connection.HTTPSConnection object at 0x14e9f7222080>: Failed to establish a new connection: [Errno 101] Network is unreachable'))
